[2025-01-08T04:21:16.502+0000] {taskinstance.py:1159} INFO - Dependencies all met for dep_context=non-requeueable deps ti=<TaskInstance: etl_socialstream_pipeline.upload_to_s3 manual__2025-01-08T04:20:01.266314+00:00 [queued]>
[2025-01-08T04:21:16.507+0000] {taskinstance.py:1159} INFO - Dependencies all met for dep_context=requeueable deps ti=<TaskInstance: etl_socialstream_pipeline.upload_to_s3 manual__2025-01-08T04:20:01.266314+00:00 [queued]>
[2025-01-08T04:21:16.507+0000] {taskinstance.py:1361} INFO - Starting attempt 1 of 4
[2025-01-08T04:21:16.511+0000] {taskinstance.py:1382} INFO - Executing <Task(PythonOperator): upload_to_s3> on 2025-01-08 04:20:01.266314+00:00
[2025-01-08T04:21:16.514+0000] {standard_task_runner.py:57} INFO - Started process 61 to run task
[2025-01-08T04:21:16.516+0000] {standard_task_runner.py:84} INFO - Running: ['airflow', 'tasks', 'run', 'etl_socialstream_pipeline', 'upload_to_s3', 'manual__2025-01-08T04:20:01.266314+00:00', '--job-id', '5', '--raw', '--subdir', 'DAGS_FOLDER/social_stream_dag.py', '--cfg-path', '/tmp/tmp4eu5a1xa']
[2025-01-08T04:21:16.518+0000] {standard_task_runner.py:85} INFO - Job 5: Subtask upload_to_s3
[2025-01-08T04:21:16.537+0000] {task_command.py:416} INFO - Running <TaskInstance: etl_socialstream_pipeline.upload_to_s3 manual__2025-01-08T04:20:01.266314+00:00 [running]> on host da4c27c408b4
[2025-01-08T04:21:16.566+0000] {taskinstance.py:1662} INFO - Exporting env vars: AIRFLOW_CTX_DAG_EMAIL='atharvnanaware01@gmail.com' AIRFLOW_CTX_DAG_OWNER='Atharv-Nanaware' AIRFLOW_CTX_DAG_ID='etl_socialstream_pipeline' AIRFLOW_CTX_TASK_ID='upload_to_s3' AIRFLOW_CTX_EXECUTION_DATE='2025-01-08T04:20:01.266314+00:00' AIRFLOW_CTX_TRY_NUMBER='1' AIRFLOW_CTX_DAG_RUN_ID='manual__2025-01-08T04:20:01.266314+00:00'
[2025-01-08T04:21:19.600+0000] {logging_mixin.py:151} INFO - The AWS Access Key Id you provided does not exist in our records.
[2025-01-08T04:21:19.906+0000] {taskinstance.py:1937} ERROR - Task failed with exception
Traceback (most recent call last):
  File "/home/airflow/.local/lib/python3.11/site-packages/s3fs/core.py", line 706, in _lsdir
    async for c in self._iterdir(
  File "/home/airflow/.local/lib/python3.11/site-packages/s3fs/core.py", line 756, in _iterdir
    async for i in it:
  File "/home/airflow/.local/lib/python3.11/site-packages/aiobotocore/paginate.py", line 30, in __anext__
    response = await self._make_request(current_kwargs)
               ^^^^^^^^^^^^^^^^^^^^^^^^^^^^^^^^^^^^^^^^
  File "/home/airflow/.local/lib/python3.11/site-packages/aiobotocore/client.py", line 383, in _make_api_call
    raise error_class(parsed_response, operation_name)
botocore.exceptions.ClientError: An error occurred (InvalidAccessKeyId) when calling the ListObjectsV2 operation: The AWS Access Key Id you provided does not exist in our records.

The above exception was the direct cause of the following exception:

Traceback (most recent call last):
  File "/home/airflow/.local/lib/python3.11/site-packages/airflow/operators/python.py", line 192, in execute
    return_value = self.execute_callable()
                   ^^^^^^^^^^^^^^^^^^^^^^^
  File "/home/airflow/.local/lib/python3.11/site-packages/airflow/operators/python.py", line 209, in execute_callable
    return self.python_callable(*self.op_args, **self.op_kwargs)
           ^^^^^^^^^^^^^^^^^^^^^^^^^^^^^^^^^^^^^^^^^^^^^^^^^^^^^
  File "/opt/airflow/pipelines/aws_s3_pipeline.py", line 13, in upload_s3_pipeline
    upload_to_s3(s3, file_path, AWS_BUCKET_NAME, file_path.split('/')[-1])
  File "/opt/airflow/etls/aws_etl.py", line 34, in upload_to_s3
    s3.put(file_path, bucket + '/raw/' + s3_file_name)
  File "/home/airflow/.local/lib/python3.11/site-packages/fsspec/asyn.py", line 118, in wrapper
    return sync(self.loop, func, *args, **kwargs)
           ^^^^^^^^^^^^^^^^^^^^^^^^^^^^^^^^^^^^^^
  File "/home/airflow/.local/lib/python3.11/site-packages/fsspec/asyn.py", line 103, in sync
    raise return_result
  File "/home/airflow/.local/lib/python3.11/site-packages/fsspec/asyn.py", line 56, in _runner
    result[0] = await coro
                ^^^^^^^^^^
  File "/home/airflow/.local/lib/python3.11/site-packages/fsspec/asyn.py", line 536, in _put
    trailing_sep(rpath) or await self._isdir(rpath)
                           ^^^^^^^^^^^^^^^^^^^^^^^^
  File "/home/airflow/.local/lib/python3.11/site-packages/s3fs/core.py", line 1411, in _isdir
    return bool(await self._lsdir(path))
                ^^^^^^^^^^^^^^^^^^^^^^^
  File "/home/airflow/.local/lib/python3.11/site-packages/s3fs/core.py", line 719, in _lsdir
    raise translate_boto_error(e)
PermissionError: The AWS Access Key Id you provided does not exist in our records.
[2025-01-08T04:21:19.932+0000] {taskinstance.py:1400} INFO - Marking task as UP_FOR_RETRY. dag_id=etl_socialstream_pipeline, task_id=upload_to_s3, execution_date=20250108T042001, start_date=20250108T042116, end_date=20250108T042119
[2025-01-08T04:21:19.949+0000] {warnings.py:109} WARNING - /home/airflow/.local/lib/python3.11/site-packages/airflow/utils/email.py:154: RemovedInAirflow3Warning: Fetching SMTP credentials from configuration variables will be deprecated in a future release. Please set credentials using a connection instead.
  send_mime_email(e_from=mail_from, e_to=recipients, mime_msg=msg, conn_id=conn_id, dryrun=dryrun)

[2025-01-08T04:21:19.950+0000] {configuration.py:1068} WARNING - section/key [smtp/smtp_user] not found in config
[2025-01-08T04:21:19.950+0000] {email.py:270} INFO - Email alerting: attempt 1
[2025-01-08T04:21:19.954+0000] {configuration.py:1068} WARNING - section/key [smtp/smtp_user] not found in config
[2025-01-08T04:21:19.954+0000] {email.py:270} INFO - Email alerting: attempt 1
[2025-01-08T04:21:19.954+0000] {taskinstance.py:2007} ERROR - Failed to send email to: ['atharvnanaware01@gmail.com']
Traceback (most recent call last):
  File "/home/airflow/.local/lib/python3.11/site-packages/s3fs/core.py", line 706, in _lsdir
    async for c in self._iterdir(
  File "/home/airflow/.local/lib/python3.11/site-packages/s3fs/core.py", line 756, in _iterdir
    async for i in it:
  File "/home/airflow/.local/lib/python3.11/site-packages/aiobotocore/paginate.py", line 30, in __anext__
    response = await self._make_request(current_kwargs)
               ^^^^^^^^^^^^^^^^^^^^^^^^^^^^^^^^^^^^^^^^
  File "/home/airflow/.local/lib/python3.11/site-packages/aiobotocore/client.py", line 383, in _make_api_call
    raise error_class(parsed_response, operation_name)
botocore.exceptions.ClientError: An error occurred (InvalidAccessKeyId) when calling the ListObjectsV2 operation: The AWS Access Key Id you provided does not exist in our records.

The above exception was the direct cause of the following exception:

Traceback (most recent call last):
  File "/home/airflow/.local/lib/python3.11/site-packages/airflow/models/taskinstance.py", line 1518, in _run_raw_task
    self._execute_task_with_callbacks(context, test_mode, session=session)
  File "/home/airflow/.local/lib/python3.11/site-packages/airflow/models/taskinstance.py", line 1681, in _execute_task_with_callbacks
    result = self._execute_task(context, task_orig)
             ^^^^^^^^^^^^^^^^^^^^^^^^^^^^^^^^^^^^^^
  File "/home/airflow/.local/lib/python3.11/site-packages/airflow/models/taskinstance.py", line 1744, in _execute_task
    result = execute_callable(context=context, **execute_callable_kwargs)
             ^^^^^^^^^^^^^^^^^^^^^^^^^^^^^^^^^^^^^^^^^^^^^^^^^^^^^^^^^^^^
  File "/home/airflow/.local/lib/python3.11/site-packages/airflow/operators/python.py", line 192, in execute
    return_value = self.execute_callable()
                   ^^^^^^^^^^^^^^^^^^^^^^^
  File "/home/airflow/.local/lib/python3.11/site-packages/airflow/operators/python.py", line 209, in execute_callable
    return self.python_callable(*self.op_args, **self.op_kwargs)
           ^^^^^^^^^^^^^^^^^^^^^^^^^^^^^^^^^^^^^^^^^^^^^^^^^^^^^
  File "/opt/airflow/pipelines/aws_s3_pipeline.py", line 13, in upload_s3_pipeline
    upload_to_s3(s3, file_path, AWS_BUCKET_NAME, file_path.split('/')[-1])
  File "/opt/airflow/etls/aws_etl.py", line 34, in upload_to_s3
    s3.put(file_path, bucket + '/raw/' + s3_file_name)
  File "/home/airflow/.local/lib/python3.11/site-packages/fsspec/asyn.py", line 118, in wrapper
    return sync(self.loop, func, *args, **kwargs)
           ^^^^^^^^^^^^^^^^^^^^^^^^^^^^^^^^^^^^^^
  File "/home/airflow/.local/lib/python3.11/site-packages/fsspec/asyn.py", line 103, in sync
    raise return_result
  File "/home/airflow/.local/lib/python3.11/site-packages/fsspec/asyn.py", line 56, in _runner
    result[0] = await coro
                ^^^^^^^^^^
  File "/home/airflow/.local/lib/python3.11/site-packages/fsspec/asyn.py", line 536, in _put
    trailing_sep(rpath) or await self._isdir(rpath)
                           ^^^^^^^^^^^^^^^^^^^^^^^^
  File "/home/airflow/.local/lib/python3.11/site-packages/s3fs/core.py", line 1411, in _isdir
    return bool(await self._lsdir(path))
                ^^^^^^^^^^^^^^^^^^^^^^^
  File "/home/airflow/.local/lib/python3.11/site-packages/s3fs/core.py", line 719, in _lsdir
    raise translate_boto_error(e)
PermissionError: The AWS Access Key Id you provided does not exist in our records.

During handling of the above exception, another exception occurred:

Traceback (most recent call last):
  File "/home/airflow/.local/lib/python3.11/site-packages/airflow/models/taskinstance.py", line 2420, in email_alert
    send_email(task.email, subject, html_content)
  File "/home/airflow/.local/lib/python3.11/site-packages/airflow/utils/email.py", line 80, in send_email
    return backend(
           ^^^^^^^^
  File "/home/airflow/.local/lib/python3.11/site-packages/airflow/utils/email.py", line 154, in send_email_smtp
    send_mime_email(e_from=mail_from, e_to=recipients, mime_msg=msg, conn_id=conn_id, dryrun=dryrun)
  File "/home/airflow/.local/lib/python3.11/site-packages/airflow/utils/email.py", line 272, in send_mime_email
    smtp_conn = _get_smtp_connection(smtp_host, smtp_port, smtp_timeout, smtp_ssl)
                ^^^^^^^^^^^^^^^^^^^^^^^^^^^^^^^^^^^^^^^^^^^^^^^^^^^^^^^^^^^^^^^^^^
  File "/home/airflow/.local/lib/python3.11/site-packages/airflow/utils/email.py", line 316, in _get_smtp_connection
    return smtplib.SMTP(host=host, port=port, timeout=timeout)
           ^^^^^^^^^^^^^^^^^^^^^^^^^^^^^^^^^^^^^^^^^^^^^^^^^^^
  File "/usr/local/lib/python3.11/smtplib.py", line 255, in __init__
    (code, msg) = self.connect(host, port)
                  ^^^^^^^^^^^^^^^^^^^^^^^^
  File "/usr/local/lib/python3.11/smtplib.py", line 341, in connect
    self.sock = self._get_socket(host, port, self.timeout)
                ^^^^^^^^^^^^^^^^^^^^^^^^^^^^^^^^^^^^^^^^^^
  File "/usr/local/lib/python3.11/smtplib.py", line 312, in _get_socket
    return socket.create_connection((host, port), timeout,
           ^^^^^^^^^^^^^^^^^^^^^^^^^^^^^^^^^^^^^^^^^^^^^^^
  File "/usr/local/lib/python3.11/socket.py", line 851, in create_connection
    raise exceptions[0]
  File "/usr/local/lib/python3.11/socket.py", line 836, in create_connection
    sock.connect(sa)
ConnectionRefusedError: [Errno 111] Connection refused

During handling of the above exception, another exception occurred:

Traceback (most recent call last):
  File "/home/airflow/.local/lib/python3.11/site-packages/airflow/models/taskinstance.py", line 2005, in handle_failure
    self.email_alert(error, task)
  File "/home/airflow/.local/lib/python3.11/site-packages/airflow/models/taskinstance.py", line 2422, in email_alert
    send_email(task.email, subject, html_content_err)
  File "/home/airflow/.local/lib/python3.11/site-packages/airflow/utils/email.py", line 80, in send_email
    return backend(
           ^^^^^^^^
  File "/home/airflow/.local/lib/python3.11/site-packages/airflow/utils/email.py", line 154, in send_email_smtp
    send_mime_email(e_from=mail_from, e_to=recipients, mime_msg=msg, conn_id=conn_id, dryrun=dryrun)
  File "/home/airflow/.local/lib/python3.11/site-packages/airflow/utils/email.py", line 272, in send_mime_email
    smtp_conn = _get_smtp_connection(smtp_host, smtp_port, smtp_timeout, smtp_ssl)
                ^^^^^^^^^^^^^^^^^^^^^^^^^^^^^^^^^^^^^^^^^^^^^^^^^^^^^^^^^^^^^^^^^^
  File "/home/airflow/.local/lib/python3.11/site-packages/airflow/utils/email.py", line 316, in _get_smtp_connection
    return smtplib.SMTP(host=host, port=port, timeout=timeout)
           ^^^^^^^^^^^^^^^^^^^^^^^^^^^^^^^^^^^^^^^^^^^^^^^^^^^
  File "/usr/local/lib/python3.11/smtplib.py", line 255, in __init__
    (code, msg) = self.connect(host, port)
                  ^^^^^^^^^^^^^^^^^^^^^^^^
  File "/usr/local/lib/python3.11/smtplib.py", line 341, in connect
    self.sock = self._get_socket(host, port, self.timeout)
                ^^^^^^^^^^^^^^^^^^^^^^^^^^^^^^^^^^^^^^^^^^
  File "/usr/local/lib/python3.11/smtplib.py", line 312, in _get_socket
    return socket.create_connection((host, port), timeout,
           ^^^^^^^^^^^^^^^^^^^^^^^^^^^^^^^^^^^^^^^^^^^^^^^
  File "/usr/local/lib/python3.11/socket.py", line 851, in create_connection
    raise exceptions[0]
  File "/usr/local/lib/python3.11/socket.py", line 836, in create_connection
    sock.connect(sa)
ConnectionRefusedError: [Errno 111] Connection refused
[2025-01-08T04:21:19.964+0000] {standard_task_runner.py:104} ERROR - Failed to execute job 5 for task upload_to_s3 (The AWS Access Key Id you provided does not exist in our records.; 61)
[2025-01-08T04:21:19.991+0000] {local_task_job_runner.py:228} INFO - Task exited with return code 1
[2025-01-08T04:21:20.011+0000] {taskinstance.py:2778} INFO - 0 downstream tasks scheduled from follow-on schedule check
